Workbook

Sheet dinamica
A2: Empreendimento | B2: (Tudo)
A3: Situação do Repasse | B3: (Vários itens)
G4: 2025 | H4: 2026
A5: Contagem de Reserva | C5: Data | H5: =D5/3 -> 0
A6: Corretor | B6: Imobiliária | C6: 2024 | D6: 2025 | E6: 2026 | F6: (vazio) | G6: Total Geral | H6: =D6/3 -> 675
A7: ARTHUR PARRIAO NEGOCIOS IMOBILIARIOS | B7: IMOBILIÁRIAS | FSA | D7: 5 | E7: 13 | G7: 18 | H7: =D7/3 -> 1.6666667
A8: ISABELLA PEREIRA FELICIANO | B8: AUTÔNOMOS | FSA | C8: 15 | D8: 19 | E8: 2 | G8: 36 | H8: =D8/3 -> 6.3333333
A9: ISABELLA PEREIRA FELICIANO | B9: AUTÔNOMOS 2 | FSA | D9: 15 | E9: 6 | G9: 21 | H9: =D9/3 -> 5
A10: CLEIDE ALVES DE OLIVEIRA | B10: AUTÔNOMOS | FSA | D10: 8 | E10: 8 | G10: 16 | H10: =D10/3 -> 2.6666667
A11: ANNA LUIZA PEREIRA DE SOUSA | B11: AUTÔNOMOS | FSA | D11: 20 | E11: 7 | G11: 27 | H11: =D11/3 -> 6.6666667
A12: MARIA EDUARDA VIEIRA DAMASCENO - CLT | B12: CANAL VIRTUAL 1 | D12: 3 | E12: 7 | G12: 10 | H12: =D12/3 -> 1
A13: MARIA EDUARDA VIEIRA DAMASCENO - CLT | B13: CANAL VIRTUAL 2 | D13: 12 | G13: 12 | H13: =D13/3 -> 4
A14: GABRIEL DO NASCIMENTO DIAS - CLT | B14: EQUIPE PRÓPRIA |FSA | C14: 27 | D14: 27 | E14: 7 | G14: 61 | H14: =D14/3 -> 9
A15: PASCOAL IMOBILIARIA | B15: IMOBILIÁRIAS | AGL | C15: 34 | D15: 23 | E15: 6 | G15: 63 | H15: =D15/3 -> 7.6666667
A16: LUCIANO PONTES SILVA JUNIOR - CLT | B16: CANAL VIRTUAL 2 | D16: 1 | E16: 6 | G16: 7 | H16: =D16/3 -> 0.33333333
A17: LUCAS PAULO MARQUES PINTO - CLT | B17: EQUIPE PRÓPRIA |FSA | D17: 6 | E17: 6 | G17: 12 | H17: =D17/3 -> 2
A18: FABIANE BEZERRA MOREIRA DOS SANTOS - CLT | B18: EQUIPE PRÓPRIA 2 | AGL | D18: 1 | E18: 5 | F18: 1 | G18: 7 | H18: =D18/3 -> 0.33333333
A19: VITÓRIA IMÓVEIS IMOB | B19: AUTÔNOMOS | FSA | C19: 14 | D19: 1 | G19: 15 | H19: =D19/3 -> 0.33333333
A20: VITÓRIA IMÓVEIS IMOB | B20: IMOBILIÁRIAS | FSA | D20: 17 | E20: 5 | G20: 22 | H20: =D20/3 -> 5.6666667
A21: MARIA EUGENIA MARTINS ALVES - CLT | B21: EQUIPE PRÓPRIA |FSA | D21: 8 | E21: 5 | G21: 13 | H21: =D21/3 -> 2.6666667
A22: 7LM - VENDAS INTERNAS NOVKA | B22: NOVKA| DF | D22: 1 | E22: 5 | F22: 17 | G22: 23 | H22: =D22/3 -> 0.33333333
A23: MARA IMOBILIARIA LTDA | B23: IMOBILIÁRIAS | FSA | D23: 8 | E23: 5 | F23: 1 | G23: 14 | H23: =D23/3 -> 2.6666667
A24: GYOVANA FERNANDES ALMEIDA CASTRO | B24: AUTÔNOMOS 2 | FSA | D24: 4 | E24: 5 | G24: 9 | H24: =D24/3 -> 1.3333333
A25: KEULLY DE SOUSA BRAGA | B25: AUTÔNOMOS | FSA | E25: 2 | G25: 2 | H25: =D25/3 -> 0
A26: KEULLY DE SOUSA BRAGA | B26: AUTÔNOMOS 2 | FSA | E26: 3 | G26: 3 | H26: =D26/3 -> 0
A27: MICAEL DOS SANTOS PIRES - CLT | B27: CANAL VIRTUAL | C27: 13 | D27: 2 | G27: 15 | H27: =D27/3 -> 0.66666667
A28: MICAEL DOS SANTOS PIRES - CLT | B28: CANAL VIRTUAL 1 | D28: 2 | G28: 2 | H28: =D28/3 -> 0.66666667
A29: MICAEL DOS SANTOS PIRES - CLT | B29: EQUIPE PRÓPRIA | AGL | D29: 10 | G29: 10 | H29: =D29/3 -> 3.3333333
A30: MICAEL DOS SANTOS PIRES - CLT | B30: EQUIPE PRÓPRIA 2 | AGL | D30: 6 | E30: 4 | G30: 10 | H30: =D30/3 -> 2
A31: INGRID ALVES D'APARECIDA - CLT | B31: EQUIPE PRÓPRIA |FSA | C31: 21 | D31: 27 | E31: 4 | G31: 52 | H31: =D31/3 -> 9
A32: NATASHA LUCÍLIA BARBOSA - CLT | B32: EQUIPE PRÓPRIA 2 | AGL | D32: 1 | E32: 4 | G32: 5 | H32: =D32/3 -> 0.33333333
A33: JULIANA MARIA DE SOUZA - CLT | B33: EQUIPE PRÓPRIA 2 | AGL | E33: 4 | G33: 4 | H33: =D33/3 -> 0
A34: DAIANA SOARES DA ROCHA | B34: AUTÔNOMOS | FSA | D34: 24 | E34: 4 | G34: 28 | H34: =D34/3 -> 8
A35: WANDERSON ROMERO COELHO DA SILVA - CLT | B35: AUTÔNOMOS | AGL | D35: 8 | E35: 1 | G35: 9 | H35: =D35/3 -> 2.6666667
A36: WANDERSON ROMERO COELHO DA SILVA - CLT | B36: EQUIPE PRÓPRIA | AGL | E36: 3 | G36: 3 | H36: =D36/3 -> 0
A37: MILENE DE ALMEIDA LIMA - CLT | B37: EQUIPE PRÓPRIA | AGL | D37: 3 | E37: 4 | G37: 7 | H37: =D37/3 -> 1
A38: LETÍCIA SANTOS DA SILVA BRITO - CLT | B38: CANAL VIRTUAL 2 | E38: 4 | G38: 4
A39: NAUANE MARTINS DA SILVA OLIVEIRA - CLT | B39: EQUIPE PRÓPRIA |FSA | C39: 16 | D39: 26 | E39: 4 | G39: 46
A40: ERAF CORRETORA DE IMÓVEIS EIRELI | B40: AUTÔNOMOS | FSA | C40: 9 | G40: 9
A41: ERAF CORRETORA DE IMÓVEIS EIRELI | B41: IMOBILIÁRIAS | FSA | D41: 8 | E41: 4 | G41: 12
...

Sheet Planilha2
E1: 46142 | G1: Repasses
C2: Imobiliária | D2: Consultores | E2: Data Início | F2: Qts Meses? | G2: 2024 | H2: 2025 | I2: 2026 | K2: IPC 2024 | L2: IPC 2025 | M2: IPC 2026 | N2: Meta | P2: Situação ? | R2: Gradadivo
A3: 1 | B3: 1 | C3: =VLOOKUP(D3,dinamica!A:B,2,0) -> AUTÔNOMOS | FSA | D3: CLEIDE ALVES DE OLIVEIRA | E3: =VLOOKUP(D3,[1]Colaboradores!$A$2:$D$65,4,0) -> 45769 | F3: =_xlfn.DAYS($E$1,E3)/30 -> 12.433333 | H3: 8 | I3: 8 | K3: =G3/12 -> 0 | L3: =H3/12 -> 0.66666667 | M3: =I3/3 -> 2.6666667 | N3: =VLOOKUP(F3,$U$8:$V$94,2) -> 2 | P3: =IF(M3>=N3,"OK","Analisar") -> OK | U3: 0-3 meses: 2 repasses ou IPC 0,66;
A4: =A3+1 -> 2 | B4: =B3+1 -> 2 | C4: =VLOOKUP(D4,dinamica!A:B,2,0) -> AUTÔNOMOS | FSA | D4: ISABELLA PEREIRA FELICIANO | E4: =VLOOKUP(D4,[1]Colaboradores!$A$2:$D$65,4,0) -> 45156 | F4: =_xlfn.DAYS($E$1,E4)/30 -> 32.866667 | G4: 15 | H4: 34 | I4: 8 | K4: =G4/12 -> 1.25 | L4: =H4/12 -> 2.8333333 | M4: =I4/3 -> 2.6666667 | N4: =VLOOKUP(F4,$U$8:$V$94,2) -> 2 | P4: =IF(M4>=N4,"OK","Analisar") -> OK | U4: 3-6 meses: 4 repasses ou IPC 1,33;
A5: =A4+1 -> 3 | B5: =B4+1 -> 3 | C5: =VLOOKUP(D5,dinamica!A:B,2,0) -> AUTÔNOMOS | FSA | D5: ANNA LUIZA PEREIRA DE SOUSA | E5: =VLOOKUP(D5,[1]Colaboradores!$A$2:$D$65,4,0) -> 45791 | F5: =_xlfn.DAYS($E$1,E5)/30 -> 11.7 | H5: 20 | I5: 7 | K5: =G5/12 -> 0 | L5: =H5/12 -> 1.6666667 | M5: =I5/3 -> 2.3333333 | N5: =VLOOKUP(F5,$U$8:$V$94,2) -> 2 | P5: =IF(M5>=N5,"OK","Analisar") -> OK | R5: Desenvolvimento | U5: 6-9 meses: 5 repasses ou IPC 1,66;
A6: =A5+1 -> 4 | B6: =B5+1 -> 4 | C6: =VLOOKUP(D6,dinamica!A:B,2,0) -> AUTÔNOMOS | FSA | D6: STEFFANY SILVA PINTO | E6: =VLOOKUP(D6,[1]Colaboradores!$A$2:$D$65,4,0) -> 45931 | F6: =_xlfn.DAYS($E$1,E6)/30 -> 7.0333333 | H6: 2 | I6: 4 | K6: =G6/12 -> 0 | L6: =H6/12 -> 0.16666667 | M6: =I6/3 -> 1.3333333 | N6: =VLOOKUP(F6,$U$8:$V$94,2) -> 1.66 | P6: =IF(M6>=N6,"OK","Analisar") -> Analisar | R6: Reposição | U6: Após 9 meses: 6 repasses ou IPC 2;
A7: =A6+1 -> 5 | B7: =B6+1 -> 5 | C7: =VLOOKUP(D7,dinamica!A:B,2,0) -> AUTÔNOMOS | FSA | D7: CAMILA FERNANDES DA SILVA | E7: =VLOOKUP(D7,[1]Colaboradores!$A$2:$D$65,4,0) -> 45261 | F7: =_xlfn.DAYS($E$1,E7)/30 -> 29.366667 | G7: 15 | H7: 19 | I7: 4 | K7: =G7/12 -> 1.25 | L7: =H7/12 -> 1.5833333 | M7: =I7/3 -> 1.3333333 | N7: =VLOOKUP(F7,$U$8:$V$94,2) -> 2 | P7: =IF(M7>=N7,"OK","Analisar") -> Analisar | R7: Críterios Definido
A8: =A7+1 -> 6 | B8: =B7+1 -> 6 | C8: =VLOOKUP(D8,dinamica!A:B,2,0) -> AUTÔNOMOS | FSA | D8: ANIBAL HAMU NETO | E8: =VLOOKUP(D8,[1]Colaboradores!$A$2:$D$65,4,0) -> 45931 | F8: =_xlfn.DAYS($E$1,E8)/30 -> 7.0333333 | H8: 1 | I8: 1 | K8: =G8/12 -> 0 | L8: =H8/12 -> 0.083333333 | M8: =I8/3 -> 0.33333333 | N8: =VLOOKUP(F8,$U$8:$V$94,2) -> 1.66 | P8: =IF(M8>=N8,"OK","Analisar") -> Analisar | U8: 0 | V8: 0.66
A9: =A8+1 -> 7 | B9: =B8+1 -> 7 | C9: =VLOOKUP(D9,dinamica!A:B,2,0) -> AUTÔNOMOS | FSA | D9: EMMANUELY FERNANDA DO NASCIMENTO | E9: =VLOOKUP(D9,[1]Colaboradores!$A$2:$D$65,4,0) -> 45882 | F9: =_xlfn.DAYS($E$1,E9)/30 -> 8.6666667 | H9: 3 | I9: 1 | K9: =G9/12 -> 0 | L9: =H9/12 -> 0.25 | M9: =I9/3 -> 0.33333333 | N9: =VLOOKUP(F9,$U$8:$V$94,2) -> 1.66 | P9: =IF(M9>=N9,"OK","Analisar") -> Analisar | R9: Racional crescimento Gradativo | U9: =1+U8 -> 1 | V9: 0.66
B10: =B9+1 -> 8 | C10: =VLOOKUP(D10,dinamica!A:B,2,0) -> AUTÔNOMOS | FSA | D10: JHENNEFE HORRARA SILVA DE OLIVEIRA | E10: =VLOOKUP(D10,[1]Colaboradores!$A$2:$D$65,4,0) -> 46084 | F10: =_xlfn.DAYS($E$1,E10)/30 -> 1.9333333 | I10: 1 | K10: =G10/12 -> 0 | L10: =H10/12 -> 0 | M10: =I10/3 -> 0.33333333 | N10: =VLOOKUP(F10,$U$8:$V$94,2) -> 0.66 | P10: =IF(M10>=N10,"OK","Analisar") -> Analisar | U10: =1+U9 -> 2 | V10: 0.66
A11: =A9+1 -> 8 | B11: =B10+1 -> 9 | C11: AUTÔNOMOS | FSA | D11: Thâmara Rafaella de Melo Santos | E11: =VLOOKUP(D11,[1]Colaboradores!$A$2:$D$65,4,0) -> 24/03/2026 | F11: =_xlfn.DAYS($E$1,E11)/30 -> 1.2333333 | N11: =VLOOKUP(F11,$U$8:$V$94,2) -> 0.66 | P11: =IF(M11>=N11,"OK","Analisar") -> Analisar | U11: =1+U10 -> 3 | V11: 0.66
A12: =A11+1 -> 9 | B12: 1 | C12: AUTÔNOMOS 2 | FSA | D12: KEULLY DE SOUSA BRAGA | E12: =VLOOKUP(D12,[1]Colaboradores!$A$2:$D$65,4,0) -> 46050 | F12: =_xlfn.DAYS($E$1,E12)/30 -> 3.0666667 | I12: 5 | K12: =G12/12 -> 0 | L12: =H12/12 -> 0 | M12: =I12/3 -> 1.6666667 | N12: =VLOOKUP(F12,$U$8:$V$94,2) -> 0.66 | P12: =IF(M12>=N12,"OK","Analisar") -> OK | R12: Replicar Gerentes | U12: =1+U11 -> 4 | V12: 1.33
A13: =A12+1 -> 10 | B13: =B12+1 -> 2 | C13: =VLOOKUP(D13,dinamica!A:B,2,0) -> AUTÔNOMOS 2 | FSA | D13: GYOVANA FERNANDES ALMEIDA CASTRO | E13: =VLOOKUP(D13,[1]Colaboradores!$A$2:$D$65,4,0) -> 45868 | F13: =_xlfn.DAYS($E$1,E13)/30 -> 9.1333333 | H13: 4 | I13: 5 | K13: =G13/12 -> 0 | L13: =H13/12 -> 0.33333333 | M13: =I13/3 -> 1.6666667 | N13: =VLOOKUP(F13,$U$8:$V$94,2) -> 1.66 | P13: =IF(M13>=N13,"OK","Analisar") -> OK | U13: =1+U12 -> 5 | V13: 1.33
A14: =A13+1 -> 11 | B14: =B13+1 -> 3 | C14: =VLOOKUP(D14,dinamica!A:B,2,0) -> AUTÔNOMOS 2 | FSA | D14: THAIRINE STEFANNI RODRIGUES DA SILVA | E14: =VLOOKUP(D14,[1]Colaboradores!$A$2:$D$65,4,0) -> 45868 | F14: =_xlfn.DAYS($E$1,E14)/30 -> 9.1333333 | H14: 4 | I14: 3 | K14: =G14/12 -> 0 | L14: =H14/12 -> 0.33333333 | M14: =I14/3 -> 1 | N14: =VLOOKUP(F14,$U$8:$V$94,2) -> 1.66 | P14: =IF(M14>=N14,"OK","Analisar") -> Analisar | R14: Rever Remunneração | U14: =1+U13 -> 6 | V14: 1.33
A15: =A14+1 -> 12 | B15: =B14+1 -> 4 | C15: AUTÔNOMOS 2 | FSA | D15: MARCILENE DOS REIS CARVALHO | E15: =VLOOKUP(D15,[1]Colaboradores!$A$2:$D$65,4,0) -> 45531 | F15: =_xlfn.DAYS($E$1,E15)/30 -> 20.366667 | G15: 1 | H15: 9 | I15: 2 | K15: =G15/12 -> 0.083333333 | L15: =H15/12 -> 0.75 | M15: =I15/3 -> 0.66666667 | N15: =VLOOKUP(F15,$U$8:$V$94,2) -> 2 | P15: =IF(M15>=N15,"OK","Analisar") -> Analisar | U15: =1+U14 -> 7 | V15: 1.66
A16: =A15+1 -> 13 | B16: =B15+1 -> 5 | C16: AUTÔNOMOS 2 | FSA | D16: LETÍCIA LORRANNY SANTOS DOURADO | E16: =VLOOKUP(D16,[1]Colaboradores!$A$2:$D$65,4,0) -> 45868 | F16: =_xlfn.DAYS($E$1,E16)/30 -> 9.1333333 | H16: 2 | I16: 2 | K16: =G16/12 -> 0 | L16: =H16/12 -> 0.16666667 | M16: =I16/3 -> 0.66666667 | N16: =VLOOKUP(F16,$U$8:$V$94,2) -> 1.66 | P16: =IF(M16>=N16,"OK","Analisar") -> Analisar | U16: =1+U15 -> 8 | V16: 1.66
A17: =A16+1 -> 14 | B17: =B16+1 -> 6 | C17: AUTÔNOMOS 2 | FSA | D17: Erika Alves Gomes | E17: =VLOOKUP(D17,[1]Colaboradores!$A$2:$D$65,4,0) -> 46099 | F17: =_xlfn.DAYS($E$1,E17)/30 -> 1.4333333 | N17: =VLOOKUP(F17,$U$8:$V$94,2) -> 0.66 | P17: =IF(M17>=N17,"OK","Analisar") -> Analisar | U17: =1+U16 -> 9 | V17: 1.66
A18: =A17+1 -> 15 | B18: =B17+1 -> 7 | C18: AUTÔNOMOS 2 | FSA | D18: Pabline Micheli Oliveira da Silva | E18: =VLOOKUP(D18,[1]Colaboradores!$A$2:$D$65,4,0) -> 46099 | F18: =_xlfn.DAYS($E$1,E18)/30 -> 1.4333333 | N18: =VLOOKUP(F18,$U$8:$V$94,2) -> 0.66 | P18: =IF(M18>=N18,"OK","Analisar") -> Analisar | U18: =1+U17 -> 10 | V18: 2
A19: =A18+1 -> 16 | B19: =B18+1 -> 8 | C19: AUTÔNOMOS 2 | FSA | D19: JOCICLEIDE FERREIRA DA PAIXÃO | E19: =VLOOKUP(D19,[1]Colaboradores!$A$2:$D$65,4,0) -> 46125 | F19: =_xlfn.DAYS($E$1,E19)/30 -> 0.56666667 | N19: =VLOOKUP(F19,$U$8:$V$94,2) -> 0.66 | P19: =IF(M19>=N19,"OK","Analisar") -> Analisar | U19: =1+U18 -> 11 | V19: 2
A20: =A19+1 -> 17 | B20: 1 | C20: EQUIPE PRÓPRIA |FSA | D20: Gabriel do Nascimento Dias | E20: =VLOOKUP(D20,[1]Colaboradores!$A$2:$D$65,4,0) -> 45231 | F20: =_xlfn.DAYS($E$1,E20)/30 -> 30.366667 | G20: 27 | H20: 27 | I20: 7 | K20: =G20/12 -> 2.25 | L20: =H20/12 -> 2.25 | M20: =I20/3 -> 2.3333333 | N20: =VLOOKUP(F20,$U$8:$V$94,2) -> 2 | P20: =IF(M20>=N20,"OK","Analisar") -> OK | U20: =1+U19 -> 12 | V20: 2
A21: =A20+1 -> 18 | B21: =B20+1 -> 2 | C21: EQUIPE PRÓPRIA |FSA | D21: Lucas Paulo Marques Pinto | E21: =VLOOKUP(D21,[1]Colaboradores!$A$2:$D$65,4,0) -> 45880 | F21: =_xlfn.DAYS($E$1,E21)/30 -> 8.7333333 | H21: 6 | I21: 6 | K21: =G21/12 -> 0 | L21: =H21/12 -> 0.5 | M21: =I21/3 -> 2 | N21: =VLOOKUP(F21,$U$8:$V$94,2) -> 1.66 | P21: =IF(M21>=N21,"OK","Analisar") -> OK | U21: =1+U20 -> 13 | V21: 2
A22: =A21+1 -> 19 | B22: =B21+1 -> 3 | C22: EQUIPE PRÓPRIA |FSA | D22: Maria Eugenia Martins alves | E22: =VLOOKUP(D22,[1]Colaboradores!$A$2:$D$65,4,0) -> 45902 | F22: =_xlfn.DAYS($E$1,E22)/30 -> 8 | H22: 8 | I22: 5 | K22: =G22/12 -> 0 | L22: =H22/12 -> 0.66666667 | M22: =I22/3 -> 1.6666667 | N22: =VLOOKUP(F22,$U$8:$V$94,2) -> 1.66 | P22: =IF(M22>=N22,"OK","Analisar") -> OK | U22: =1+U21 -> 14 | V22: 2
A23: =A22+1 -> 20 | B23: =B22+1 -> 4 | C23: EQUIPE PRÓPRIA |FSA | D23: INGRID ALVES DAPARECIDA | E23: =VLOOKUP(D23,[1]Colaboradores!$A$2:$D$65,4,0) -> 45267 | F23: =_xlfn.DAYS($E$1,E23)/30 -> 29.166667 | G23: 21 | H23: 27 | I23: 4 | K23: =G23/12 -> 1.75 | L23: =H23/12 -> 2.25 | M23: =I23/3 -> 1.3333333 | N23: =VLOOKUP(F23,$U$8:$V$94,2) -> 2 | P23: =IF(M23>=N23,"OK","Analisar") -> Analisar | U23: =1+U22 -> 15 | V23: 2
A24: =A23+1 -> 21 | B24: =B23+1 -> 5 | C24: EQUIPE PRÓPRIA |FSA | D24: Nauane Martins Da Silva Oliveira | E24: =VLOOKUP(D24,[1]Colaboradores!$A$2:$D$65,4,0) -> 23/08/2023 | F24: =_xlfn.DAYS($E$1,E24)/30 -> 32.7 | G24: 16 | H24: 26 | I24: 4 | K24: =G24/12 -> 1.3333333 | L24: =H24/12 -> 2.1666667 | M24: =I24/3 -> 1.3333333 | N24: =VLOOKUP(F24,$U$8:$V$94,2) -> 2 | P24: =IF(M24>=N24,"OK","Analisar") -> Analisar | U24: =1+U23 -> 16 | V24: 2
A25: =A24+1 -> 22 | B25: =B24+1 -> 6 | C25: EQUIPE PRÓPRIA |FSA | D25: Ryan Gomes Calazans | E25: =VLOOKUP(D25,[1]Colaboradores!$A$2:$D$65,4,0) -> 45231 | F25: =_xlfn.DAYS($E$1,E25)/30 -> 30.366667 | G25: 23 | H25: 21 | I25: 3 | K25: =G25/12 -> 1.9166667 | L25: =H25/12 -> 1.75 | M25: =I25/3 -> 1 | N25: =VLOOKUP(F25,$U$8:$V$94,2) -> 2 | P25: =IF(M25>=N25,"OK","Analisar") -> Analisar | U25: =1+U24 -> 17 | V25: 2
A26: =A25+1 -> 23 | B26: =B25+1 -> 7 | C26: EQUIPE PRÓPRIA |FSA | D26: MARIA DAIANA DA SILVA BRANDAO | E26: =VLOOKUP(D26,[1]Colaboradores!$A$2:$D$65,4,0) -> 45902 | F26: =_xlfn.DAYS($E$1,E26)/30 -> 8 | H26: 4 | I26: 2 | K26: =G26/12 -> 0 | L26: =H26/12 -> 0.33333333 | M26: =I26/3 -> 0.66666667 | N26: =VLOOKUP(F26,$U$8:$V$94,2) -> 1.66 | P26: =IF(M26>=N26,"OK","Analisar") -> Analisar | U26: =1+U25 -> 18 | V26: 2
A27: =A26+1 -> 24 | B27: =B26+1 -> 8 | C27: EQUIPE PRÓPRIA |FSA | D27: SAMARA FEITOSA VALADARES GENEROSO | E27: =VLOOKUP(D27,[1]Colaboradores!$A$2:$D$65,4,0) -> 21/05/2025 | F27: =_xlfn.DAYS($E$1,E27)/30 -> 11.466667 | H27: 8 | K27: =G27/12 -> 0 | L27: =H27/12 -> 0.66666667 | M27: =I27/3 -> 0 | N27: =VLOOKUP(F27,$U$8:$V$94,2) -> 2 | P27: =IF(M27>=N27,"OK","Analisar") -> Analisar | U27: =1+U26 -> 19 | V27: 2
A28: =A27+1 -> 25 | B28: =B27+1 -> 9 | C28: EQUIPE PRÓPRIA |FSA | D28: Valmir Santana dos Santos | E28: =VLOOKUP(D28,[1]Colaboradores!$A$2:$D$65,4,0) -> 18/03/2026 | F28: =_xlfn.DAYS($E$1,E28)/30 -> 1.4333333 | N28: =VLOOKUP(F28,$U$8:$V$94,2) -> 0.66 | P28: =IF(M28>=N28,"OK","Analisar") -> Analisar | U28: =1+U27 -> 20 | V28: 2
A29: =A28+1 -> 26 | B29: =B28+1 -> 10 | C29: EQUIPE PRÓPRIA |FSA | D29: MURIELLY DE SOUSA SANTOS | E29: =VLOOKUP(D29,[1]Colaboradores!$A$2:$D$65,4,0) -> 18/03/2026 | F29: =_xlfn.DAYS($E$1,E29)/30 -> 1.4333333 | N29: =VLOOKUP(F29,$U$8:$V$94,2) -> 0.66 | P29: =IF(M29>=N29,"OK","Analisar") -> Analisar | U29: =1+U28 -> 21 | V29: 2
A30: =A29+1 -> 27 | B30: =B29+1 -> 11 | C30: EQUIPE PRÓPRIA |FSA | D30: NATÁLIA NOGUEIRA AGUIAR | E30: =VLOOKUP(D30,[1]Colaboradores!$A$2:$D$65,4,0) -> 46118 | F30: =_xlfn.DAYS($E$1,E30)/30 -> 0.8 | N30: =VLOOKUP(F30,$U$8:$V$94,2) -> 0.66 | P30: =IF(M30>=N30,"OK","Analisar") -> Analisar | U30: =1+U29 -> 22 | V30: 2
C31: EQUIPE PRÓPRIA |FSA | D31: LEONARD LUIS MOGENA PEREZ - CLT | E31: =VLOOKUP(D31,[1]Colaboradores!$A$2:$D$65,4,0) -> #N/A | F31: Desligados | H31: 9 | I31: 1 | K31: =G31/12 -> 0 | L31: =H31/12 -> 0.75 | M31: =I31/3 -> 0.33333333 | N31: =VLOOKUP(F31,$U$8:$V$94,2) -> #N/A | P31: Desligado | U31: =1+U30 -> 23 | V31: 2
A32: =A30+1 -> 28 | B32: 1 | C32: CANAL VIRTUAL 1 | D32: MARIA EDUARDA VIEIRA DAMASCENO | E32: =VLOOKUP(D32,[1]Colaboradores!$A$2:$D$65,4,0) -> 45384 | F32: =_xlfn.DAYS($E$1,E32)/30 -> 25.266667 | H32: 15 | I32: 7 | K32: =G32/12 -> 0 | L32: =H32/12 -> 1.25 | M32: =I32/3 -> 2.3333333 | N32: =VLOOKUP(F32,$U$8:$V$94,2) -> 2 | P32: =IF(M32>=N32,"OK","Analisar") -> OK | U32: =1+U31 -> 24 | V32: 2
A33: =A32+1 -> 29 | B33: =B32+1 -> 2 | C33: CANAL VIRTUAL 1 | D33: Daniel Andrade dos Santos | E33: =VLOOKUP(D33,[1]Colaboradores!$A$2:$D$65,4,0) -> 45566 | F33: =_xlfn.DAYS($E$1,E33)/30 -> 19.2 | G33: 2 | H33: 28 | I33: 3 | K33: =G33/12 -> 0.16666667 | L33: =H33/12 -> 2.3333333 | M33: =I33/3 -> 1 | N33: =VLOOKUP(F33,$U$8:$V$94,2) -> 2 | P33: =IF(M33>=N33,"OK","Analisar") -> Analisar | U33: =1+U32 -> 25 | V33: 2
A34: =A33+1 -> 30 | B34: =B33+1 -> 3 | C34: CANAL VIRTUAL 1 | D34: LUCAS DE SOUZA RODRIGUES | E34: =VLOOKUP(D34,[1]Colaboradores!$A$2:$D$65,4,0) -> 46028 | F34: =_xlfn.DAYS($E$1,E34)/30 -> 3.8 | I34: 2 | K34: =G34/12 -> 0 | L34: =H34/12 -> 0 | M34: =I34/3 -> 0.66666667 | N34: =VLOOKUP(F34,$U$8:$V$94,2) -> 0.66 | P34: =IF(M34>=N34,"OK","Analisar") -> OK | U34: =1+U33 -> 26 | V34: 2
A35: =A34+1 -> 31 | B35: =B34+1 -> 4 | C35: CANAL VIRTUAL 1 | D35: CAIO BRENDON LOPES MARTINS | E35: =VLOOKUP(D35,[1]Colaboradores!$A$2:$D$65,4,0) -> 21/07/2025 | F35: =_xlfn.DAYS($E$1,E35)/30 -> 9.4333333 | H35: 2 | I35: 1 | K35: =G35/12 -> 0 | L35: =H35/12 -> 0.16666667 | M35: =I35/3 -> 0.33333333 | N35: =VLOOKUP(F35,$U$8:$V$94,2) -> 1.66 | P35: =IF(M35>=N35,"OK","Analisar") -> Analisar | U35: =1+U34 -> 27 | V35: 2
A36: =A35+1 -> 32 | B36: =B35+1 -> 5 | C36: CANAL VIRTUAL 1 | D36: LUCAS RAMOS DA VICTÓRIA | E36: =VLOOKUP(D36,[1]Colaboradores!$A$2:$D$65,4,0) -> 46118 | F36: =_xlfn.DAYS($E$1,E36)/30 -> 0.8 | N36: =VLOOKUP(F36,$U$8:$V$94,2) -> 0.66 | P36: =IF(M36>=N36,"OK","Analisar") -> Analisar | U36: =1+U35 -> 28 | V36: 2
A37: =A36+1 -> 33 | B37: =B36+1 -> 6 | C37: CANAL VIRTUAL 1 | D37: MARTA ANASTACIO NERES | E37: =VLOOKUP(D37,[1]Colaboradores!$A$2:$D$65,4,0) -> 21/12/2023 | F37: =_xlfn.DAYS($E$1,E37)/30 -> 28.7 | N37: =VLOOKUP(F37,$U$8:$V$94,2) -> 2 | P37: =IF(M37>=N37,"OK","Analisar") -> Analisar | U37: =1+U36 -> 29 | V37: 2
A38: =A37+1 -> 34 | B38: =B37+1 -> 7 | C38: CANAL VIRTUAL 1 | D38: LUIS RAFAEL DO ROSARIO | E38: =VLOOKUP(D38,[1]Colaboradores!$A$2:$D$65,4,0) -> 23/06/2025 | F38: =_xlfn.DAYS($E$1,E38)/30 -> 10.366667 | H38: 3 | K38: =G38/12 -> 0 | L38: =H38/12 -> 0.25 | M38: =I38/3 -> 0 | N38: =VLOOKUP(F38,$U$8:$V$94,2) -> 2 | P38: =IF(M38>=N38,"OK","Analisar") -> Analisar | U38: =1+U37 -> 30 | V38: 2
A39: =A38+1 -> 35 | B39: 1 | C39: =VLOOKUP(D45,dinamica!A:B,2,0) -> CANAL VIRTUAL 2 | D39: LETICIA SANTOS DA SILVA | E39: =VLOOKUP(D39,[1]Colaboradores!$A$2:$D$65,4,0) -> 18/11/2025 | F39: =_xlfn.DAYS($E$1,E39)/30 -> 5.4333333 | I39: 4 | K39: =G39/12 -> 0 | L39: =H39/12 -> 0 | M39: =I39/3 -> 1.3333333 | N39: =VLOOKUP(F39,$U$8:$V$94,2) -> 1.33 | P39: =IF(M39>=N39,"OK","Analisar") -> OK | U39: =1+U38 -> 31 | V39: 2
A40: =A39+1 -> 36 | B40: =B39+1 -> 2 | C40: CANAL VIRTUAL 2 | D40: SANDRA SANTANA DOS SANTOS | E40: =VLOOKUP(D40,[1]Colaboradores!$A$2:$D$65,4,0) -> 45141 | F40: =_xlfn.DAYS($E$1,E40)/30 -> 33.366667 | G40: 1 | H40: 16 | I40: 2 | K40: =G40/12 -> 0.083333333 | L40: =H40/12 -> 1.3333333 | M40: =I40/3 -> 0.66666667 | N40: =VLOOKUP(F40,$U$8:$V$94,2) -> 2 | P40: =IF(M40>=N40,"OK","Analisar") -> Analisar | U40: =1+U39 -> 32 | V40: 2
...

Sheet 20260409120513_69d7c029a4692
A1: Número | B1: Situação do Repasse | C1: Reserva | D1: Empreendimento | E1: Etapa | F1: Bloco | G1: Unidade | H1: Região | I1: Cliente | J1: Documento do Cliente | K1: Imobiliária | L1: Corretor | M1: Parcela | N1: Contrato Quitado | O1: Contrato Liquidado | P1: Registro Pago | Q1: ITBI Pago | R1: Laudêmio Pago | S1: Recebendo financiamento | T1: Valor previsto | U1: Parcela de conclusão | V1: Saldo devedor | W1: Valor da dívida | X1: Valor do subsídio | Y1: Valor do FGTS | Z1: Valor financiado | AA1: Medição Obra | AB1: % de medição de obra | AC1: Próxima ação | AD1: Nº do contrato | AE1: Contrato | AF1: Nº de matrícula | AG1: Data do registro | AH1: Valor do registro | AI1: Data de Assinatura | AJ1: Data | AK1: Data de contabilização de contrato | AL1: Data do contrato liberado | AM1: Data de unidade liberada | AN1: Data de laudo liberado | AO1: Data de recurso liberado | AP1: Correspondente | AQ1: Usuário correspondente | AR1: Banco | AS1: Agência | AT1: Data de alteração do status | AU1: Data da última alteração | AV1: Situação da Reserva | AW1: Data de Venda | AX1: Código Interno da Reserva | AY1: Valor Contrato | AZ1: Tipo de Venda | BA1: Sigla do Empreendimento | BB1: Contrato Interno | BC1: Nome - Documento do Associado | BD1: Cidade | BE1: Estado | BF1: Telefone | BG1: Endereço | BH1: Cep | BI1: Bairro | BJ1: Email | BK1: Celular | BL1: Renda | BM1: Vencimento da Aprovação | BN1: Grupo de Situações | BO1: Última Mensagem | BP1: Data Última Mensagem | BQ1: Código Interno Unidade | BR1: Código Interno Cliente | BS1: Profissão do Cliente | BT1: Data da Solicitação Da Confissão de Dívida | BU1: Valor do Produto Caixa | BV1: Data de pagamento do produto CAIXA | BW1: Aprovado pela Secretaria de Vendas | BX1: Data Vencimento | Produto Caixa | BY1: N° da Ficha AGEHAB | BZ1: Data da Aprovação da SV | CA1: Data do recebimento do contrato CEF (FISICO ASSINADO) | CB1: Protocolo - ONR | CC1: Data de cadastro da ficha AGEHAB | CD1: Unidade no CV x Unidade contrato CEF conferem? | CE1: AP - PRODUTO | CF1: Data do Envio da Confissão de Divida | CG1: Data da Inconformidade CEHOP | CH1: Tipo de Exceção | CI1: Data do Reenvio CEHOP | CJ1: Data Pagamento do ITBI | CK1: Confissão de Divida Com Exceção | CL1: Data da Assinatura da Confissão de Divida | CM1: Data de Protocolo no Cartório | CN1: Data do Envio da Ficha | CO1: Data Solicitação do Contrato AGEHAB | CP1: Data de Solicitação do ITBI-Prefeitura | CQ1: Excedente de cobrança | CR1: Data Da Aprovação da Ficha AGEHAB | CS1: Data da Validação do Espelho | CT1: Data de validade da avaliação SICAQ | CU1: Data Solicitação Pagamento ITBI-Financeiro | CV1: Data do Recebimento do Contrato AGEHAB | CW1: Data do Espelho Anexado | CX1: Data de Pagamento do Registro | CY1: Aprovado Espelho pela SV | CZ1: Data da Exigência | DA1: FGTS Futuro | DB1: Data de Envio Comitê CEF | DC1: Data do Cumprimento da Exigência | DD1: Data do Kit Registro OK | DE1: Data da Emissão da Minuta CAIXA | DF1: Data de Envio da Solicitação de Garantia | DG1: Protocolo - ITBI | DH1: Obs Garantia | DI1: Data da conformidade da Garantia | DJ1: Data Envio CEHOP | DK1: Data de Envio Contrato AGEHAB e 7LM ao Repasse | DL1: Data da Assinatura Contrato AGEHAB | DM1: Data do Recebimento Contrato AGEHAB e 7LM do Repasse | DN1: Data do Envio do Contrato a AGEHAB | DO1: Data Conformida de CEHOP | DP1: Contrato Validado Pela AGEHAB | DQ1: Data de solicitação de credito ONR | DR1: Fichas com Pendência | DS1: Situação Prenotação | DT1: Título Prenotação | DU1: Título Taxa de Registro | DV1: Situação Taxa Registro | DW1: Data agendamento CEF | DX1: Score Fiador | DY1: AP - ITBI | DZ1: ONR | EA1: Obs Cartório | EB1: Obs Prefeitura | EC1: Origem Clube | ED1: Titulo | EE1: Valor ITBI | EF1: Obs. Sinal | EG1: Situação Sinal | EH1: Obs. AGEHAB | EI1: Obs. Caixa | EJ1: Obs. Fiador | EK1: Probabilidade de assinatura
A2: 3181 | B2: PROCESSO FINALIZADO | C2: 3703 | D2: FSA009 - VILA DOS IPÊS | E2: Única | F2: BLOCO E | G2: 3 | H2: FORMOSA | I2: PEDRO HENRIQUE MARTINS CINTRA | J2: "04813989101" | K2: AUTÔNOMOS | FSA | L2: AMANDA SOUZA PEREIRA | M2: Não | N2: Não | O2: Não | P2: Não | Q2: Não | R2: Não | S2: Não | T2: 152100.93 | U2: 600 | V2: 0 | W2: 116205.93 | X2: 35895 | Y2: 0 | Z2: 152100.93 | AA2: 0 | AB2: 0 | AD2: 8787718825423 | AE2: Contrato Adimplente | AF2: 740228 | AG2: 45365 | AH2: 2705.72 | AI2: 45309 | AJ2: 2004 | AK2: 45294 | AP2: Endy Carvalho Consultoria imobiliária | AT2: 45484 | AU2: 45484 | AV2: VENDA FINALIZADA | AW2: 45279 | AX2: 19519 | AY2: 217100.93 | BA2: FSA09 | BB2: 19519 | BD2: Formosa | BE2: Goiás | BF2: 5562999626525 | BG2: Via 13, QD CH, 240, L. 0, BLOCO G | BH2: 73802419 | BI2: Setor Sul | BJ2: pedrocintra.agro@gmail.com | BL2: 2000 | BM2: 45452 | BQ2: 3095 | BR2: 5375 | BS2: Autônomo(a) | BT2: 45279 | BW2: sim | BY2: MP134432 | BZ2: 45279 | CA2: 45309 | CC2: 45299 | CD2: Sim | CF2: 45279 | CL2: 45295 | CM2: 45324 | CN2: 45299 | CO2: 45323 | CP2: 45315 | CR2: 45301 | CS2: 45295 | CT2: 45452 | CV2: 45338 | CW2: 45295 | CY2: Sim | DB2: 45307 | DD2: 45316 | DE2: 45308 | DF2: 45365 | DI2: 45387 | DJ2: 45293 | DK2: 45338 | DL2: 45344 | DM2: 45357 | DN2: 45383 | DO2: 45295 | DP2: OK
A3: 3182 | B3: PROCESSO FINALIZADO | C3: 3719 | D3: FSA009 - VILA DOS IPÊS | E3: Única | F3: BLOCO Q | G3: 203 | H3: FORMOSA | I3: VANESSA PEREIRA MATEUS | J3: "04311812175" | K3: AUTÔNOMOS | FSA | L3: ALANA RABELO DA COSTA | M3: Não | N3: Não | O3: Não | P3: Não | Q3: Não | R3: Não | S3: Não | T3: 138176.1 | U3: 705 | V3: 0 | W3: 133779.1 | X3: 4397 | Y3: 0 | Z3: 138176.1 | AA3: 0 | AB3: 0 | AD3: 8787718868467 | AE3: Contrato Adimplente | AF3: 74228 | AG3: 45419 | AH3: 2794.99 | AI3: 45324 | AJ3: 2004 | AK3: 45294 | AP3: Endy Carvalho Consultoria imobiliária | AT3: 45484 | AU3: 45484 | AV3: VENDA FINALIZADA | AW3: 45288 | AX3: 19520 | AY3: 195000.4 | BA3: FSA09 | BB3: 19520 | BD3: Formosa | BE3: Goiás | BF3: 556181488530 | BG3: RUA 17, Q 117, L 9 | BH3: 73813240 | BI3: Formosinha | BJ3: vanessapmateus@gmail.com | BL3: 2600 | BM3: 45459 | BQ3: 3291 | BR3: 5376 | BS3: Administrador | BT3: 45289 | BW3: sim | BY3: MP134429 | BZ3: 45289 | CA3: 45324 | CC3: 45295 | CD3: Sim | CF3: 45289 | CG3: 45299 | CI3: 45299 | CL3: 45295 | CM3: 45379 | CN3: 45295 | CO3: 45337 | CR3: 45299 | CS3: 45321 | CT3: 45459 | CU3: 45364 | CV3: 45338 | CW3: 45321 | CY3: Sim | DB3: 45323 | DD3: 45327 | DE3: 45324 | DF3: 45420 | DI3: 45421 | DJ3: 45295 | DK3: 45338 | DL3: 45365 | DM3: 45371 | DN3: 45383 | DO3: 45321 | DP3: OK | EE3: 1972.69
A4: 3183 | B4: PROCESSO FINALIZADO | C4: 3673 | D4: FSA009 - VILA DOS IPÊS | E4: Única | F4: BLOCO D | G4: 301 | H4: FORMOSA | I4: MARCO ANTONIO ALVES DE SOUSA | J4: "08188049123" | K4: AUTÔNOMOS | FSA | L4: VITÓRIA IMÓVEIS IMOB | M4: Não | N4: Não | O4: Não | P4: Não | Q4: Não | R4: Não | S4: Não | T4: 158378.66 | U4: 594 | V4: 0 | W4: 123432.66 | X4: 35470 | Y4: 0 | Z4: 158902.66 | AA4: 0 | AB4: 0 | AD4: 8787718828767 | AE4: Contrato Adimplente | AF4: 74022 | AG4: 45359 | AH4: 2705.72 | AI4: 45314 | AJ4: 2004 | AK4: 45295 | AP4: Endy Carvalho Consultoria imobiliária | AT4: 45484 | AU4: 45484 | AV4: VENDA FINALIZADA | AW4: 45266 | AX4: 19555 | AY4: 205000.02 | BA4: FSA09 | BB4: 19555 | BD4: Formosa | BE4: Goiás | BF4: 556198789745 | BG4: RUA 13 QUADRA 10 LOTE 8 | BH4: 73808305 | BI4: Parque Vila Verde | BJ4: Alvesmarco6161@gmail.com | BL4: 1980 | BM4: 45439 | BQ4: 3085 | BR4: 5377 | BS4: Auxiliar de Serviços Gerais | BT4: 45289 | BW4: sim | BY4: MP134440 | BZ4: 45289 | CA4: 45320 | CC4: 45302 | CD4: Sim | CF4: 45289 | CL4: 45296 | CM4: 45338 | CN4: 45302 | CO4: 45323 | CP4: 45322 | CR4: 45303 | CS4: 45287 | CT4: 45439 | CV4: 45338 | CW4: 45287 | CY4: Sim | DB4: 45307 | DD4: 45327 | DE4: 45309 | DF4: 45360 | DI4: 45363 | DJ4: 45282 | DK4: 45338 | DL4: 45350 | DM4: 45357 | DN4: 45383 | DO4: 45286 | DP4: OK
A5: 3184 | B5: PROCESSO FINALIZADO | C5: 3717 | D5: FSA009 - VILA DOS IPÊS | E5: Única | F5: BLOCO J | G5: 302 | H5: FORMOSA | I5: CRISTIANA DAS DORES BEZERRA | J5: "01989023100" | K5: EQUIPE PRÓPRIA |FSA | L5: TAKADA IMOB | M5: Não | N5: Não | O5: Não | P5: Não | Q5: Não | R5: Não | S5: Não | T5: 149640.3 | U5: 647.7 | V5: 0 | W5: 121181.98 | X5: 28884 | Y5: 0 | Z5: 150065.98 | AA5: 0 | AB5: 0 | AD5: 8787718907039 | AE5: Contrato Adimplente | AF5: 74119 | AG5: 45348 | AH5: 2794.99 | AI5: 45307 | AJ5: 2004 | AK5: 45295 | AP5: Endy Carvalho Consultoria imobiliária | AT5: 45484 | AU5: 45484 | AV5: VENDA FINALIZADA | AW5: 45288 | AX5: 19558 | AY5: 205000.1 | BA5: FSA09 | BB5: 19558 | BD5: Cabeceiras | BE5: Goiás | BF5: 5561999165094 | BG5: Rua Benedito Ribeiro, Q. 10, L. 13A | BH5: 73870000 | BI5: Setor Mariano Machado | BJ5: cristianadores12@gmail.com | BL5: 2158.99 | BM5: 45100 | BQ5: 3174 | BR5: 5380 | BS5: Auxiliar | BT5: 45288 | BW5: sim | BY5: MP13443 | BZ5: 45288 | CA5: 45309 | CC5: 45295 | CD5: Sim | CF5: 45288 | CL5: 45296 | CM5: 45324 | CN5: 45295 | CO5: 45323 | CP5: 45315 | CR5: 45296 | CS5: 45302 | CT5: 45466 | CV5: 45338 | CW5: 45302 | CY5: Sim | DB5: 45303 | DD5: 45306 | DE5: 45306 | DF5: 45349 | DI5: 45350 | DJ5: 45299 | DK5: 45338 | DL5: 45356 | DM5: 45357 | DN5: 45383 | DO5: 45302 | DP5: OK
A6: 3185 | B6: PROCESSO FINALIZADO | C6: 3707 | D6: FSA009 - VILA DOS IPÊS | E6: Única | F6: BLOCO I | G6: 301 | H6: FORMOSA | I6: KAYLANE KAREN FERREIRA DE OLIVEIRA | J6: "09372448133" | K6: AUTÔNOMOS | FSA | L6: MATEUS VITOR DIAS - DESLIGADO | M6: Não | N6: Não | O6: Não | P6: Não | Q6: Não | R6: Não | S6: Não | T6: 151587.93 | U6: 0 | V6: 0 | W6: 116972.93 | X6: 35128 | Y6: 0 | Z6: 152100.93 | AA6: 0 | AB6: 0 | AD6: 8787718868114 | AE6: Contrato Adimplente | AF6: 74102 | AG6: 45348 | AH6: 1794.89 | AI6: 45314 | AJ6: 2004 | AK6: 45295 | AP6: Endy Carvalho Consultoria imobiliária | AT6: 45484 | AU6: 45484 | AV6: VENDA FINALIZADA | AW6: 45280 | AX6: 19557 | AY6: 207000.73 | BA6: FSA09 | BB6: 19557 | BD6: Formosa | BE6: Goiás | BF6: 5561999930487 | BG6: Rua 15, Q. 41, | BH6: 73805216 | BI6: Jardim Oliveira | BJ6: kayllane.karen12@gmail.com | BL6: 2000 | BM6: 45457 | BQ6: 3165 | BR6: 5379 | BS6: Vendedor(a) | BT6: 45288 | BW6: sim | BY6: MP134441 | BZ6: 45288 | CA6: 45320 | CC6: 45302 | CD6: Sim | CF6: 45288 | CL6: 45296 | CM6: 45338 | CN6: 45302 | CO6: 45323 | CP6: 45322 | CR6: 45303 | CS6: 45296 | CT6: 45457 | CV6: 45338 | CW6: 45295 | CY6: Sim | DB6: 45307 | DD6: 45317 | DE6: 45314 | DF6: 45349 | DI6: 45350 | DJ6: 45290 | DK6: 45338 | DL6: 45350 | DM6: 45357 | DN6: 45383 | DO6: 45293 | DP6: OK
A7: 3186 | B7: PROCESSO FINALIZADO | C7: 3724 | D7: FSA007 - VILA DAS HORTÊNSIAS | E7: Etapa | F7: BLOCO B | G7: 3 | H7: FORMOSA | I7: MATHEUS BATISTA BALDOINO | J7: "05194042116" | K7: EQUIPE PRÓPRIA |FSA | L7: FERNANDO FONSECA DE DEUS GALVÃO - CLT- DESLIGADO | M7: Não | N7: Não | O7: Não | P7: Não | Q7: Não | R7: Não | S7: Não | T7: 151620.01 | U7: 600 | V7: 0 | W7: 115858.9 | X7: 35895 | Y7: 0 | Z7: 151753.9 | AA7: 0 | AB7: 0 | AD7: 8787718899834 | AE7: Contrato Adimplente | AF7: 72657 | AG7: 45457 | AH7: 5515.43 | AI7: 45343 | AJ7: 2004 | AK7: 45295 | AP7: Endy Carvalho Consultoria imobiliária | AT7: 46098 | AU7: 46098 | AV7: VENDA FINALIZADA | AW7: 45289 | AX7: 19560 | AY7: 220000 | BA7: FSA07 | BB7: 19560 | BD7: Formosa | BE7: Goiás | BF7: 5561996990087 | BG7: Rua CRUNDWALD COSTA, Q 40 | BH7: 73807840 | BI7: Jardim Califórnia | BJ7: matheusbfsa@hotmail.com | BL7: 2000 | BM7: 45467 | BO7: Bruno Macário (Gestor): Cliente precisou ser reavaliado, pois a agência não aceitou o faturamento da Empresa dele. Com isso, o cliente está aguardando conformidade no momento. Vou retornar a fase anterior. | BP7: 31/01/2024 às 12h32 | BQ7: 854 | BR7: 5382 | BS7: Auxiliar | BT7: 45290 | BW7: sim | BY7: MP139498 | BZ7: 45290 | CA7: 45341 | CC7: 45295 | CD7: Sim | CF7: 45290 | CG7: 45323 | CI7: 45324 | CL7: 45296 | CM7: 45358 | CN7: 45295 | CO7: 45352 | CR7: 45296 | CS7: 45330 | CT7: 45467 | CV7: 45364 | CW7: 45330 | CY7: Sim | DD7: 45300 | DF7: 45457 | DI7: 45460 | DJ7: 45295 | DK7: 45364 | DL7: 45463 | DM7: 45502 | DN7: 46057 | DP7: 46057
A8: 3187 | B8: PROCESSO FINALIZADO | C8: 3714 | D8: AGL028 - VILA DO CERRADO | E8: ETAPA 01 | F8: BLOCO A | G8: 304 | H8: ÁGUAS LINDAS | I8: GIZELLA FERREIRA DOS SANTOS MOREIRA | J8: "73032913187" | K8: EQUIPE PRÓPRIA | AGL | L8: MAYSA GABRIELA GONÇALVES OLIVEIRA - CLT | M8: Não | N8: Não | O8: Não | P8: Sim | Q8: Sim | R8: Não | S8: Não | T8: 159215.6 | U8: 544.5 | V8: 0 | W8: 111109.23 | X8: 47654 | Y8: 0.01 | Z8: 158763.24 | AA8: 0 | AB8: 0 | AE8: Contrato Adimplente | AF8: 96022 | AG8: 45316 | AH8: 2740.25 | AI8: 45303 | AJ8: 2004 | AK8: 45295 | AP8: Endy Carvalho Consultoria imobiliária | AT8: 45653 | AU8: 45744 | AV8: VENDA FINALIZADA | AW8: 45287 | AX8: 19559 | AY8: 203222.55 | BA8: AGL28 | BB8: 19559 | BD8: Águas Lindas de Goiás | BE8: Goiás | BF8: 5561998773302 | BG8: Q C-08 L 04 | BH8: 72910000 | BI8: MANSOES VILLAGE | BJ8: GIZELINHAMARIA.MOREIRA@GMAIL.COM | BL8: 1815 | BM8: 45460 | BQ8: 2712 | BR8: 5381 | BS8: Servente | BT8: 45287 | BU8: 500 | BV8: 45310 | BX8: 45315 | BY8: MP129681 | BZ8: 45287 | CA8: 45306 | CC8: 45296 | CD8: Sim | CF8: 45287 | CG8: 45295 | CI8: 45295 | CJ8: 45307 | CL8: 45296 | CM8: 45308 | CN8: 45296 | CO8: 45323 | CP8: 45306 | CR8: 45299 | CS8: 45296 | CU8: 45307 | CV8: 45329 | CW8: 45296 | CY8: Sim | DD8: 45289 | DF8: 45317 | DI8: 45322 | DJ8: 45320 | DK8: 45329 | DL8: 45339 | DM8: 45345 | DN8: 45624 | DO8: 45296 | DP8: 45624 | EE8: 4029.63
A9: 3188 | B9: PROCESSO FINALIZADO | C9: 3698 | D9: AGL028 - VILA DO CERRADO | E9: ETAPA 01 | F9: BLOCO U | G9: 304 | H9: ÁGUAS LINDAS | I9: IGOR OLIVEIRA MAIA | J9: "06154176120" | K9: EQUIPE PRÓPRIA | AGL | L9: MAYSA GABRIELA GONÇALVES OLIVEIRA - CLT | M9: Não | N9: Não | O9: Não | P9: Sim | Q9: Sim | R9: Não | S9: Não | T9: 155762.32 | U9: 593.87 | V9: 79827.04 | W9: 115493.34 | X9: 39840 | Y9: 0 | Z9: 155333.34 | AA9: 0 | AB9: 0 | AD9: 8787718888166 | AE9: Contrato Adimplente | AF9: 96342 | AG9: 45316 | AH9: 2740.25 | AI9: 45302 | AJ9: 2004 | AK9: 45295 | AP9: Endy Carvalho Consultoria imobiliária | AT9: 45653 | AU9: 45744 | AV9: VENDA FINALIZADA | AW9: 45276 | AX9: 19556 | AY9: 197333.34 | BA9: AGL28 | BB9: 19556 | BD9: Águas Lindas de Goiás | BE9: Goiás | BF9: 5561994159998 | BG9: CHAC 24 QUADRA Q | BH9: 72910000 | BI9: SETOR COIMBRA CHACARA | BJ9: Igorr11@live.com | BL9: 1979.6 | BM9: 45432 | BQ9: 3053 | BR9: 5378 | BS9: Atendente | BT9: 45276 | BU9: 501.6 | BV9: 45303 | BX9: 45307 | BY9: MP129682 | BZ9: 45276 | CA9: 45303 | CC9: 45296 | CD9: Sim | CF9: 45276 | CG9: 45295 | CJ9: 45307 | CL9: 45296 | CM9: 45308 | CN9: 45296 | CO9: 45323 | CP9: 45306 | CR9: 45299 | CS9: 45296 | CU9: 45307 | CV9: 45329 | CW9: 45295 | CY9: Sim | DD9: 45293 | DF9: 45317 | DI9: 45322 | DJ9: 45294 | DK9: 45329 | DL9: 45334 | DM9: 45345 | DN9: 45624 | DO9: 45295 | DP9: 45624 | EE9: 3981.32
A10: 3189 | B10: PROCESSO FINALIZADO | C10: 3711 | D10: AGL028 - VILA DO CERRADO | E10: ETAPA 01 | F10: BLOCO C | G10: 204 | H10: ÁGUAS LINDAS | I10: SARA DE JESUS GONCALVES | J10: "06955895125" | K10: EQUIPE PRÓPRIA | AGL | L10: JOSUÉ GOMES DE SOUZA | M10: Não | N10: Não | O10: Não | P10: Sim | Q10: Sim | R10: Não | S10: Não | T10: 135725.53 | U10: 610.57 | V10: 0 | W10: 115800 | X10: 19790 | Y10: 3248 | Z10: 138838 | AA10: 0 | AB10: 0 | AD10: 8787718856361 | AE10: Contrato Adimplente | AF10: 96050 | AG10: 45362 | AH10: 2740.25 | AI10: 45343 | AJ10: 2004 | AK10: 45299 | AP10: Endy Carvalho Consultoria imobiliária | AT10: 45653 | AU10: 45744 | AV10: VENDA FINALIZADA | AW10: 45280 | AX10: 19639 | AY10: 190000.33 | BA10: AGL28 | BB10: 19639 | BD10: Águas Lindas de Goiás | BE10: Goiás | BF10: 5561999798938 | BG10: RUA 11 -A Q 79 BLOCO 16 LT 10 CONJUNTO A | BH10: 72910000 | BI10: SETOR 12 | BJ10: sj24136@gmail.com | BL10: 2481.3 | BO10: Gledson Carlos da Silva leandro (Gestor): Aguardando finalização do distrato de contrato de FI anteriormente assinado. | BP10: 17/01/2024 às 11h37 | BQ10: 2733 | BR10: 1228 | BS10: Auxiliar | BT10: 45280 | BU10: 500 | BV10: 45344 | BX10: 45350 | BY10: MP129683 | BZ10: 45280 | CA10: 45349 | CC10: 45299 | CD10: Sim | CF10: 45280 | CG10: 45338 | CI10: 45338 | CJ10: 45356 | CL10: 45299 | CM10: 45357 | CN10: 45299 | CO10: 45352 | CP10: 45349 | CR10: 45299 | CS10: 45341 | CU10: 45349 | CV10: 45363 | CW10: 45341 | CX10: 45359 | CY10: Sim | DD10: 45297 | DF10: 45363 | DI10: 45364 | DJ10: 45316 | DK10: 45364 | DL10: 45379 | DM10: 45386 | DN10: 45624 | DO10: 45341 | DP10: 45624 | EE10: 3981.32
A11: 3190 | B11: PROCESSO FINALIZADO | C11: 3723 | D11: FSA009 - VILA DOS IPÊS | E11: Única | F11: BLOCO A | G11: 202 | H11: FORMOSA | I11: JOÃO PAULO PIERDONA | J11: "06384149117" | K11: AUTÔNOMOS | FSA | L11: BRUNO SOARES BEZERRA - PARCEIRO | M11: Não | N11: Não | O11: Não | P11: Não | Q11: Não | R11: Não | S11: Não | T11: 164200 | U11: 1016.14 | V11: 0 | W11: 161635 | X11: 2565 | Y11: 0 | Z11: 164200 | AA11: 0 | AB11: 0 | AD11: 8787718908159 | AE11: Contrato Adimplente | AF11: 73971 | AG11: 45344 | AH11: 3171.57 | AI11: 45310 | AJ11: 2004 | AK11: 45299 | AP11: Endy Carvalho Consultoria imobiliária | AT11: 45484 | AU11: 45484 | AV11: VENDA FINALIZADA | AW11: 45289 | AX11: 19646 | AY11: 213119.02 | BA11: FSA09 | BB11: 19646 | BD11: Formosa | BE11: Goiás | BF11: 5561999678206 | BG11: Rua Visconde de Porto Seguro | BH11: 73801010 | BI11: Centro | BJ11: joaopaulopierdona@hotmail.com | BL11: 3432 | BM11: 45454 | BQ11: 3034 | BR11: 364 | BS11: Motorista | BT11: 45289 | BW11: sim | BY11: MP134431 | BZ11: 45289 | CA11: 45313 | CC11: 45299 | CD11: Sim | CF11: 45289 | CL11: 45300 | CM11: 45329 | CN11: 45299 | CO11: 45323 | CP11: 45315 | CR11: 45299 | CS11: 45307 | CT11: 45453 | CV11: 45338 | CW11: 45307 | CY11: Sim | DB11: 45307 | DD11: 45321 | DE11: 45309 | DF11: 45348 | DI11: 45350 | DJ11: 45303 | DK11: 45338 | DL11: 45366 | DM11: 45379 | DN11: 45383 | DO11: 45306 | DP11: OK
A12: 3191 | B12: PROCESSO FINALIZADO | C12: 3726 | D12: AGL028 - VILA DO CERRADO | E12: ETAPA 02 | F12: BLOCO T | G12: 203 | H12: ÁGUAS LINDAS | I12: THEOALBERTO JEFERSON VILA NOVA LIMBERG | J12: "02310779121" | K12: CANAL VIRTUAL | L12: JÉSSICA NOGUEIRA DE SOUSA - CLT | M12: Não | N12: Não | O12: Não | P12: Sim | Q12: Sim | R12: Não | S12: Não | T12: 132578.74 | U12: 536.07 | V12: 0 | W12: 100417.74 | X12: 30883 | Y12: 0 | Z12: 131300.74 | AA12: 0 | AB12: 0 | AD12: 8787718918421 | AE12: Contrato Adimplente | AG12: 45330 | AH12: 2740.25 | AI12: 45317 | AJ12: 2004 | AK12: 45299 | AP12: Endy Carvalho Consultoria imobiliária | AT12: 45741 | AU12: 45741 | AV12: VENDA FINALIZADA | AW12: 45290 | AX12: 19640 | AY12: 185000.86 | BA12: AGL28 | BB12: 19640 | BD12: Ceilândia | BE12: Distrito Federal | BF12: 5561993093348 | BG12: QNP 28 CJ Z | BH12: 72235824 | BI12: CEILANDIA SUL | BJ12: th.limberg22@gmail.com | BL12: 2144.29 | BQ12: 3031 | BR12: 5383 | BS12: Operador de Loja | BT12: 45310 | BU12: 500 | BV12: 45320 | BW12: sim | BX12: 45324 | BY12: MP129807 | BZ12: 45310 | CA12: 45320 | CC12: 45299 | CD12: Sim | CF12: 45310 | CG12: 45393 | CJ12: 45322 | CL12: 45313 | CM12: 45324 | CN12: 45299 | CO12: 45323 | CP12: 45320 | CR12: 45302 | CS12: 45303 | CU12: 45320 | CV12: 45329 | CW12: 45303 | CY12: Sim | DD12: 45297 | DF12: 45331 | DI12: 45338 | DJ12: 45299 | DK12: 45329 | DL12: 45332 | DM12: 45345 | DN12: 45548 | DO12: 45302 | DP12: 45548 | EE12: 3981.32
A13: 3192 | B13: PROCESSO FINALIZADO | C13: 3728 | D13: FSA009 - VILA DOS IPÊS | E13: Única | F13: BLOCO K | G13: 302 | H13: FORMOSA | I13: ALINE DE JESUS | J13: "05550067196" | K13: EQUIPE PRÓPRIA |FSA | L13: GABRIEL DO NASCIMENTO DIAS - CLT | M13: Não | N13: Não | O13: Não | P13: Não | Q13: Não | R13: Não | S13: Não | T13: 158808.28 | U13: 600 | V13: 0 | W13: 124715.28 | X13: 34606 | Y13: 0 | Z13: 159321.28 | AA13: 0 | AB13: 0 | AD13: 8787718917484 | AE13: Contrato Adimplente | AF13: 74135 | AG13: 45348 | AH13: 2794.99 | AI13: 45313 | AJ13: 2004 | AK13: 45299 | AP13: Endy Carvalho Consultoria imobiliária | AT13: 45484 | AU13: 45484 | AV13: VENDA FINALIZADA | AW13: 45300 | AX13: 19647 | AY13: 212608.44 | BA13: FSA09 | BB13: 19647 | BD13: Formosa | BE13: Goiás | BF13: 5561999121003 | BG13: Rua 29, Q. 03, | BH13: 73802025 | BI13: Setor Bosque | BJ13: lnk_00@hotmail.com | BL13: 2000 | BM13: 45471 | BQ13: 3198 | BR13: 5386 | BS13: Auxiliar | BT13: 45293 | BW13: sim | BY13: MP134433 | BZ13: 45293 | CA13: 45313 | CC13: 45299 | CD13: Sim | CF13: 45293 | CL13: 45300 | CM13: 45329 | CN13: 45299 | CO13: 45323 | CR13: 45301 | CS13: 45302 | CT13: 45468 | CV13: 45338 | CW13: 45302 | CY13: Sim | DB13: 45307 | DD13: 45329 | DE13: 45309 | DF13: 45349 | DI13: 45350 | DJ13: 45299 | DK13: 45338 | DL13: 45349 | DM13: 45357 | DN13: 45383 | DO13: 45302 | DP13: OK
A14: 3193 | B14: PROCESSO FINALIZADO | C14: 3729 | D14: FSA009 - VILA DOS IPÊS | E14: Única | F14: BLOCO G | G14: 204 | H14: FORMOSA | I14: CAIO VITOR SILVERIO SANTANA | J14: "05141790150" | K14: AUTÔNOMOS | FSA | L14: ANA CAROLINA FERREIRA DE ANDRADE - CARLOS ANDRADE IMOBILIÁRIA | M14: Não | N14: Não | O14: Não | P14: Não | Q14: Não | R14: Não | S14: Não | T14: 151313.36 | U14: 1051.03 | V14: 0 | W14: 149503.36 | X14: 1811 | Y14: 0 | Z14: 151314.36 | AA14: 0 | AB14: 0 | AD14: 8787718918146 | AE14: Contrato Adimplente | AF14: 74069 | AG14: 45362 | AH14: 3207 | AI14: 45308 | AJ14: 2004 | AK14: 45299 | AP14: Endy Carvalho Consultoria imobiliária | AT14: 45484 | AU14: 45484 | AV14: VENDA FINALIZADA | AW14: 45300 | AX14: 19648 | AY14: 205113.64 | BA14: FSA09 | BB14: 19648 | BD14: Formosa | BE14: Goiás | BF14: 5561996341087 | BG14: Rua 7, Q.44, L. 2A | BH14: 73813420 | BI14: Formosinha | BJ14: caio.silver.98@gmail.com | BL14: 4204.17 | BM14: 45476 | BQ14: 3125 | BR14: 5387 | BS14: Auxiliar | BT14: 45295 | BW14: sim | BY14: MP134435 | BZ14: 45295 | CA14: 45309 | CC14: 45299 | CD14: Sim | CF14: 45295 | CJ14: 45323 | CL14: 45300 | CM14: 45324 | CN14: 45299 | CO14: 45323 | CP14: 45315 | CR14: 45301 | CS14: 45303 | CT14: 45474 | CV14: 45338 | CW14: 45303 | CY14: Sim | DB14: 45303 | DD14: 45308 | DE14: 45306 | DF14: 45361 | DI14: 45363 | DJ14: 45299 | DK14: 45338 | DL14: 45348 | DM14: 45357 | DN14: 45383 | DO14: 45302 | DP14: OK
A15: 3194 | B15: PROCESSO FINALIZADO | C15: 3730 | D15: FSA009 - VILA DOS IPÊS | E15: Única | F15: BLOCO H | G15: 101 | H15: FORMOSA | I15: KARISME RODRIGUES DE SOUSA | J15: "05443756109" | K15: AUTÔNOMOS | FSA | L15: JANDER JACKSON VENANCIO DE SOUZA- DESLIGADO | M15: Não | N15: Não | O15: Não | P15: Não | Q15: Não | R15: Não | S15: Não | T15: 156350.43 | U15: 710.16 | V15: 0 | W15: 134782.43 | X15: 21890 | Y15: 0 | Z15: 156672.43 | AA15: 0 | AB15: 0 | AD15: 8787718918723 | AE15: Contrato Adimplente | AF15: 74078 | AG15: 45345 | AH15: 2794.99 | AI15: 45310 | AJ15: 2004 | AK15: 45299 | AP15: Endy Carvalho Consultoria imobiliária | AT15: 45484 | AU15: 45484 | AV15: VENDA FINALIZADA | AW15: 45300 | AX15: 19649 | AY15: 215001.07 | BA15: FSA09 | BB15: 19649 | BD15: Formosa | BE15: Goiás | BF15: 5561996319166 | BG15: Avenida Circular, Q. 47 | BH15: 73805207 | BI15: Jardim Oliveira | BJ15: karinemacedo71@gmail.com | BL15: 2367.21 | BM15: 45473 | BQ15: 3144 | BR15: 5388 | BS15: Auxiliar | BT15: 45309 | BW15: sim | BY15: MP134434 | BZ15: 45309 | CA15: 45313 | CC15: 45299 | CD15: Sim | CF15: 45309 | CL15: 45309 | CM15: 45324 | CN15: 45299 | CO15: 45323 | CP15: 45315 | CR15: 45301 | CS15: 45303 | CT15: 45473 | CV15: 45338 | CW15: 45303 | CY15: Sim | DB15: 45309 | DD15: 45310 | DE15: 45309 | DF15: 45348 | DI15: 45350 | DJ15: 45299 | DK15: 45338 | DL15: 45344 | DM15: 45357 | DN15: 45383 | DO15: 45302 | DP15: OK
A16: 3195 | B16: PROCESSO FINALIZADO | C16: 3732 | D16: AGL028 - VILA DO CERRADO | E16: ETAPA 01 | F16: BLOCO D | G16: 104 | H16: ÁGUAS LINDAS | I16: MARIELLY CRISTINA MACHADO DO NASCIMENTO | J16: "61985243377" | K16: EQUIPE PRÓPRIA | AGL | L16: WELLINGTON ARAUJO - CLT | M16: Não | N16: Não | O16: Não | P16: Sim | Q16: Sim | R16: Não | S16: Não | T16: 155767.38 | U16: 594 | V16: 0 | W16: 115946.38 | X16: 39821 | Y16: 0 | Z16: 155767.38 | AA16: 0 | AB16: 0 | AD16: 8787718918065 | AE16: Contrato Adimplente | AF16: 96062 | AG16: 45316 | AH16: 2740.25 | AI16: 45308 | AJ16: 2004 | AK16: 45299 | AP16: Endy Carvalho Consultoria imobiliária | AT16: 45653 | AU16: 45744 | AV16: VENDA FINALIZADA | AW16: 45300 | AX16: 19650 | AY16: 205767.38 | BA16: AGL28 | BB16: 19650 | BD16: Águas Lindas de Goiás | BE16: Goiás | BF16: 5534984428805 | BG16: Q 45 L 05 CONJUNTO A | BH16: 72910000 | BI16: SETOR 8 | BJ16: mariellycristina627@gmail.com | BL16: 1980 | BM16: 45475 | BQ16: 2756 | BR16: 5389 | BS16: Auxiliar de Serviços Gerais | BT16: 45295 | BU16: 500 | BV16: 45310 | BX16: 45315 | BY16: MP129684 | BZ16: 45295 | CA16: 45309 | CC16: 45299 | CD16: Sim | CF16: 45295 | CJ16: 45310 | CL16: 45300 | CM16: 45313 | CN16: 45299 | CO16: 45323 | CP16: 45309 | CR16: 45300 | CS16: 45303 | CU16: 45309 | CV16: 45329 | CW16: 45303 | CY16: Sim | DB16: 45303 | DD16: 45299 | DF16: 45317 | DI16: 45322 | DJ16: 45299 | DK16: 45329 | DL16: 45458 | DM16: 45629 | DN16: 45624 | DO16: 45302 | DP16: 45624 | EE16: 3981.32
A17: 3196 | B17: PROCESSO FINALIZADO | C17: 3722 | D17: AGL028 - VILA DO CERRADO | E17: ETAPA 01 | F17: BLOCO W | G17: 3 | H17: ÁGUAS LINDAS | I17: RENE TORRE DOS SANTOS | J17: "10235632406" | K17: EQUIPE PRÓPRIA | AGL | L17: JOSUÉ GOMES DE SOUZA | M17: Não | N17: Não | O17: Não | P17: Sim | Q17: Sim | R17: Não | S17: Não | T17: 163541.32 | U17: 579 | V17: 0 | W17: 120260.32 | X17: 43281 | Y17: 0 | Z17: 163541.32 | AA17: 0 | AB17: 0 | AD17: 8787718932513 | AE17: Contrato Adimplente | AG17: 45329 | AH17: 2740.25 | AI17: 45314 | AJ17: 2004 | AK17: 45299 | AP17: Endy Carvalho Consultoria imobiliária | AT17: 45653 | AU17: 45744 | AV17: VENDA FINALIZADA | AW17: 45288 | AX17: 19645 | AY17: 210541.32 | BA17: AGL28 | BB17: 19645 | BD17: Águas Lindas de Goiás | BE17: Goiás | BF17: 5561987308967 | BG17: Quadra 38 02/03 | BH17: 72915099 | BI17: Jardim Brasília | BJ17: renetorre20@hotmail.com | BK17: 558187308967 | BL17: 1930 | BM17: 45467 | BQ17: 3074 | BR17: 5385 | BS17: Tecnico em tecnologia da informação | BT17: 45288 | BU17: 500 | BV17: 45316 | BX17: 45322 | BY17: MP129686 | BZ17: 45288 | CA17: 45320 | CC17: 45300 | CD17: Sim | CF17: 45288 | CG17: 45306 | CJ17: 45322 | CL17: 45300 | CM17: 45324 | CN17: 45300 | CO17: 45323 | CP17: 45320 | CR17: 45300 | CS17: 45313 | CU17: 45320 | CV17: 45329 | CW17: 45313 | CY17: Sim | DD17: 45297 | DF17: 45330 | DI17: 45331 | DJ17: 45303 | DK17: 45330 | DL17: 45336 | DM17: 45345 | DN17: 45624 | DO17: 45313 | DP17: 45624 | EE17: 4165.32
A18: 3197 | B18: PROCESSO FINALIZADO | C18: 3672 | D18: AGL028 - VILA DO CERRADO | E18: ETAPA 01 | F18: BLOCO D | G18: 3 | H18: ÁGUAS LINDAS | I18: ALINE LEIA DA SILVA PENHA | J18: "05079223103" | K18: CANAL VIRTUAL | L18: CRISTIANO SANTOS PEREIRA - CLT | M18: Não | N18: Não | O18: Não | P18: Sim | Q18: Sim | R18: Não | S18: Não | T18: 155918.28 | U18: 558.82 | V18: 0 | W18: 108751.28 | X18: 47104 | Y18: 0 | Z18: 155855.28 | AA18: 0 | AB18: 0 | AD18: 8787718802830 | AE18: Contrato Adimplente | AF18: 96057 | AG18: 45370 | AH18: 2721.61 | AI18: 45337 | AJ18: 2004 | AK18: 45299 | AP18: Endy Carvalho Consultoria imobiliária | AT18: 45652 | AU18: 45744 | AV18: VENDA FINALIZADA | AW18: 45266 | AX18: 19644 | AY18: 205000.2 | BA18: AGL28 | BB18: 19644 | BD18: Águas Lindas de Goiás | BE18: Goiás | BF18: 5561998735384 | BG18: RUA 6 QUADRA 12 | BH18: 72910000 | BI18: JARDIM DA BARRAGEM III | BJ18: aline84nx@gmail.com | BL18: 1862.78 | BM18: 45444 | BO18: Gledson Carlos da Silva leandro (Gestor): Aguardando nada consta de imovel registrado. CEF consta cliente como vendedora de imovel. | BP18: 17/01/2024 às 11h36 | BQ18: 2751 | BR18: 5384 | BS18: Tecnico em Enfermagem | BT18: 45296 | BU18: 500 | BV18: 45342 | BX18: 45344 | BY18: MP129685 | BZ18: 45296 | CA18: 45342 | CC18: 45300 | CD18: Sim | CF18: 45296 | CG18: 45330 | CI18: 45328 | CJ18: 45344 | CL18: 45300 | CM18: 45345 | CN18: 45300 | CO18: 45352 | CP18: 45342 | CQ18: 2721.61 | CR18: 45300 | CS18: 45330 | CU18: 45342 | CV18: 45363 | CW18: 45330 | CX18: 45369 | CY18: Sim | DD18: 45275 | DF18: 45371 | DI18: 45372 | DJ18: 45303 | DK18: 45364 | DL18: 45370 | DM18: 45386 | DN18: 45624 | DO18: 45330 | DP18: 45624 | EE18: 4165.32
A19: 3198 | B19: DISTRATO | C19: 3715 | D19: AGL028 - VILA DO CERRADO | E19: ETAPA 01 | F19: BLOCO G | G19: 104 | H19: ÁGUAS LINDAS | I19: FRANCISCO LISBOA OLINVINDA | J19: "13651653889" | K19: EQUIPE PRÓPRIA | AGL | L19: WELLINGTON ARAUJO - CLT | M19: Não | N19: Não | O19: Não | P19: Não | Q19: Não | R19: Não | S19: Não | T19: 126860.63 | U19: 594 | V19: 0 | W19: 85371 | X19: 41299 | Y19: 0 | Z19: 126670 | AA19: 0 | AB19: 0 | AE19: Contrato Adimplente | AH19: 0 | AK19: 45300 | AP19: Endy Carvalho Consultoria imobiliária | AT19: 45322 | AU19: 45322 | AV19: DISTRATO | AW19: 45287 | AX19: 19661 | AY19: 188897.2 | BA19: AGL28 | BB19: 19661 | BC19: PAULA FERNANDA DE CARVALHO LISBOA - 06009099641 | BD19: Águas Lindas de Goiás | BE19: Goiás | BF19: 5561982891785 | BG19: GLEBA A L 21A | BH19: 72910000 | BI19: LAGO DO DESCOBERTO | BJ19: FRANCISCOLISBOA749@GMAIL.COM | BL19: 1980 | BM19: 45451 | BO19: Gledson Carlos da Silva leandro (Gestor): Cliente sinalizou desistência em razão de não ter fiador. | BP19: 17/01/2024 às 11h36 | BQ19: 2807 | BR19: 5390 | BS19: Psicólogo | BY19: MP129687 | CC19: 45300 | CN19: 45300 | CR19: 45307 | CS19: 45308 | CW19: 45307 | CY19: Sim | DD19: 45288 | DJ19: 45301 | DO19: 45306
A20: 3199 | B20: DISTRATO | C20: 3708 | D20: FSA009 - VILA DOS IPÊS | E20: Única | F20: BLOCO B | G20: 201 | H20: FORMOSA | I20: ANA VITÓRIA FIGUEIREDO FERREIRA | J20: "70842803165" | K20: EQUIPE PRÓPRIA |FSA | L20: NAUANE MARTINS DA SILVA OLIVEIRA - CLT | M20: Não | N20: Não | O20: Não | P20: Não | Q20: Não | R20: Não | S20: Não | T20: 146395.51 | U20: 472.42 | V20: 63604.49 | W20: 91395.51 | X20: 55000 | Y20: 0 | Z20: 146395.51 | AA20: 0 | AB20: 0 | AE20: Contrato Adimplente | AH20: 0 | AK20: 45300 | AP20: Endy Carvalho Consultoria imobiliária | AT20: 45349 | AU20: 45349 | AV20: DISTRATO | AW20: 45280 | AX20: 19729 | AY20: 205000.31 | BA20: FSA09 | BB20: 19729 | BD20: Formosa | BE20: Goiás | BF20: 5561998733299 | BG20: RUA TOPAZIO Q 01 | BH20: 73807805 | BI20: JARDIM CALIFÓRNIA | BJ20: anavitoriaferrefig@gmail.com | BL20: 2600 | BM20: 45460 | BQ20: 3044 | BR20: 5392 | BS20: Caixa | BY20: MP134439 | CC20: 45301 | CG20: 45308 | CN20: 45301 | CR20: 45302 | CT20: 45460 | DD20: 45306 | DJ20: 45302
A21: 3200 | B21: DISTRATO | C21: 3720 | D21: FSA007 - VILA DAS HORTÊNSIAS | E21: Etapa | F21: BLOCO K | G21: 4 | H21: FORMOSA | I21: HILLARY CAMPELO DE JESUS | J21: "06998358105" | K21: AUTÔNOMOS | FSA | L21: JE EMPREENDIMENTOS IMOBILIÁRIOS | M21: Não | N21: Não | O21: Não | P21: Não | Q21: Não | R21: Não | S21: Não | T21: 157375.84 | U21: 625.28 | V21: 0 | W21: 126015.84 | X21: 31360 | Y21: 0 | Z21: 157375.84 | AA21: 0 | AB21: 0 | AE21: Contrato Adimplente | AH21: 0 | AK21: 45300 | AP21: Endy Carvalho Consultoria imobiliária | AT21: 45369 | AU21: 45369 | AV21: DISTRATO | AW21: 45288 | AX21: 19730 | AY21: 215000.09 | BA21: FSA07 | BB21: 19730 | BD21: Formosa | BE21: Goiás | BF21: 5562998612879 | BG21: RUA 12, Q. 11 | BH21: 73808310 | BI21: PARQUE VILA VERDE | BJ21: hillarycampello@gmail.com | BL21: 2084.28 | BM21: 45431 | BQ21: 1005 | BR21: 5393 | BS21: Atendente | BY21: MP139499 | CC21: 45301 | CG21: 45307 | CN21: 45301 | CR21: 45301 | CT21: 45431 | DJ21: 45301
A22: 3201 | B22: PROCESSO FINALIZADO | C22: 3733 | D22: FSA009 - VILA DOS IPÊS | E22: Única | F22: BLOCO O | G22: 203 | H22: FORMOSA | I22: DANILO ALVES PAPA | J22: "01832826120" | K22: AUTÔNOMOS | FSA | L22: CAMILA FERNANDES DA SILVA | M22: Não | N22: Não | O22: Não | P22: Não | Q22: Não | R22: Não | S22: Não | T22: 151467.16 | U22: 480 | V22: 0 | W22: 97797.16 | X22: 53702 | Y22: 0 | Z22: 151499.16 | AA22: 0 | AB22: 0 | AD22: 8787718953740 | AE22: Contrato Adimplente | AF22: 74196 | AG22: 45516 | AH22: 0 | AI22: 45349 | AJ22: 2004 | AK22: 45300 | AP22: Endy Carvalho Consultoria imobiliária | AT22: 45484 | AU22: 45555 | AV22: VENDA FINALIZADA | AW22: 45302 | AX22: 19732 | AY22: 206000.76 | BA22: FSA09 | BB22: 19732 | BD22: Formosa | BE22: Goiás | BF22: 5561996765545 | BG22: Rua São Pedro | BH22: 73807160 | BI22: Setor Nordeste | BJ22: danilo.a.papa@outlook.com | BL22: 1600 | BM22: 45473 | BQ22: 3259 | BR22: 5395 | BS22: Assistente | BT22: 45296 | BW22: sim | BY22: MP134438 | BZ22: 44931 | CA22: 45345 | CC22: 45301 | CD22: Sim | CF22: 45296 | CG22: 45323 | CI22: 45324 | CL22: 45302 | CM22: 45391 | CN22: 45301 | CO22: 45352 | CR22: 45302 | CS22: 45327 | CT22: 45302 | CV22: 45364 | CW22: 45325 | CY22: Sim | DD22: 45355 | DF22: 45553 | DI22: 45554 | DJ22: 45302 | DK22: 45364 | DL22: 45365 | DM22: 45371 | DN22: 45383 | DO22: 45324 | DP22: OK
A23: 3202 | B23: PROCESSO FINALIZADO | C23: 3736 | D23: FSA009 - VILA DOS IPÊS | E23: Única | F23: BLOCO K | G23: 103 | H23: FORMOSA | I23: THAYNÁ DA SILVA LIMA | J23: "08427039182" | K23: EQUIPE PRÓPRIA |FSA | L23: GABRIEL DO NASCIMENTO DIAS - CLT | M23: Não | N23: Não | O23: Não | P23: Não | Q23: Não | R23: Não | S23: Não | T23: 151421.64 | U23: 649.09 | V23: 0 | W23: 122332.64 | X23: 28661 | Y23: 0 | Z23: 150993.64 | AA23: 0 | AB23: 0 | AD23: 8787718944643 | AE23: Contrato Adimplente | AG23: 45386 | AH23: 3559.94 | AI23: 45362 | AJ23: 2004 | AK23: 45300 | AP23: Endy Carvalho Consultoria imobiliária | AT23: 45743 | AU23: 45743 | AV23: VENDA FINALIZADA | AW23: 45302 | AX23: 19733 | AY23: 205221.64 | BA23: FSA09 | BB23: 19733 | BD23: Formosa | BE23: Goiás | BF23: 5561999801092 | BG23: RUA 23 | BH23: 73813350 | BI23: FORMOSINHA | BJ23: Limathaynadasilva2@gmail.com | BL23: 2153.66 | BM23: 45475 | BQ23: 3191 | BR23: 5396 | BS23: Atendente | BT23: 45299 | BW23: sim | BY23: MP134436 | BZ23: 45299 | CA23: 45357 | CC23: 45301 | CD23: Sim | CF23: 45299 | CG23: 45308 | CI23: 45351 | CL23: 45302 | CM23: 45373 | CN23: 45301 | CO23: 45366 | CP23: 45365 | CR23: 45301 | CS23: 45352 | CT23: 45475 | CV23: 45366 | CW23: 45352 | CY23: Sim | DB23: 45352 | DD23: 45303 | DE23: 45357 | DF23: 45386 | DI23: 45387 | DJ23: 45301 | DK23: 45387 | DL23: 45462 | DM23: 45504 | DN23: 45728 | DO23: 45352 | DP23: 45728
A24: 3203 | B24: DISTRATO | C24: 3725 | D24: FSA009 - VILA DOS IPÊS | E24: Única | F24: BLOCO B | G24: 203 | H24: FORMOSA | I24: EDUARDA GAIA LIMA DOS SANTOS | J24: "09884070199" | K24: AUTÔNOMOS | FSA | L24: MILENA BOTELHO DE PAIVA DIAS | M24: Não | N24: Não | O24: Não | P24: Não | Q24: Não | R24: Não | S24: Não | T24: 146950.69 | U24: 475.2 | V24: 0 | W24: 91950.69 | X24: 55000 | Y24: 0 | Z24: 146950.69 | AA24: 0 | AB24: 0 | AE24: Contrato Adimplente | AH24: 0 | AK24: 45301 | AP24: Endy Carvalho Consultoria imobiliária | AT24: 45349 | AU24: 45349 | AV24: DISTRATO | AW24: 45289 | AX24: 19731 | AY24: 200750.69 | BA24: FSA09 | BB24: 19731 | BD24: Formosa | BE24: Goiás | BF24: 5561996383737 | BG24: Rua 24 Q 140 L 09 | BH24: 73813360 | BI24: Formosinha | BJ24: dudahgaia0@gmail.com | BL24: 2350 | BM24: 45461 | BQ24: 3054 | BR24: 5394 | BS24: Atendente | BY24: MP134437 | CC24: 45301 | CF24: 45290 | CG24: 45309 | CL24: 45302 | CN24: 45301 | CR24: 45301 | CT24: 45461 | DJ24: 45303
A25: 3204 | B25: PROCESSO FINALIZADO | C25: 3735 | D25: FSA007 - VILA DAS HORTÊNSIAS | E25: Etapa | F25: BLOCO L | G25: 4 | H25: FORMOSA | I25: GEOVANE DA ROCHA NASCIMENTO | J25: "05108008155" | K25: CANAL VIRTUAL | L25: JÉSSICA NOGUEIRA DE SOUSA - CLT | M25: Não | N25: Não | O25: Não | P25: Não | Q25: Não | R25: Não | S25: Não | T25: 168000 | U25: 750 | V25: 0 | W25: 150447 | X25: 42000 | Y25: 0 | Z25: 192447 | AA25: 0 | AB25: 0 | AD25: 8787718954851 | AE25: Contrato Adimplente | AF25: 72818 | AG25: 45355 | AH25: 3171.57 | AI25: 45316 | AJ25: 2004 | AK25: 45302 | AP25: Endy Carvalho Consultoria imobiliária | AT25: 45749 | AU25: 45888 | AV25: VENDA FINALIZADA | AW25: 45303 | AX25: 19807 | AY25: 218000 | BA25: FSA07 | BB25: 19807 | BD25: Formosa | BE25: Goiás | BF25: 5561999346007 | BG25: AV. FERROVIARIA E Q M | BH25: 73807330 | BI25: SETOR NORDESTE | BJ25: geovanedarochanascimento@gmail.com | BL25: 2800 | BM25: 45477 | BQ25: 837 | BR25: 5397 | BS25: Motorista | BT25: 45299 | BW25: sim | BY25: MP139500 | BZ25: 45299 | CA25: 45320 | CC25: 45302 | CD25: Sim | CF25: 45299 | CJ25: 45334 | CL25: 45303 | CM25: 45345 | CN25: 45302 | CO25: 45323 | CP25: 45322 | CR25: 45308 | CS25: 45309 | CT25: 45477 | CU25: 45327 | CV25: 45338 | CW25: 45308 | CY25: Sim | DB25: 45309 | DD25: 45344 | DE25: 23/01/1024 | DF25: 45355 | DI25: 45356 | DJ25: 45302 | DK25: 45338 | DL25: 45341 | DM25: 45357 | DN25: 45435 | DO25: 45308 | DP25: 45435 | EE25: 2013.84
A26: 3205 | B26: PROCESSO FINALIZADO | C26: 3738 | D26: FSA009 - VILA DOS IPÊS | E26: Única | F26: BLOCO I | G26: 203 | H26: FORMOSA | I26: BIANCA ALVES DOS SANTOS | J26: "04231492107" | K26: EQUIPE PRÓPRIA |FSA | L26: KÁLITA CRISTINE MARTINS FRADE - CLT | M26: Não | N26: Não | O26: Não | P26: Não | Q26: Não | R26: Não | S26: Não | T26: 151967.22 | U26: 660 | V26: 0 | W26: 125034.22 | X26: 26934 | Y26: 0 | Z26: 151968.22 | AA26: 0 | AB26: 0 | AD26: 8787718955173 | AE26: Contrato Adimplente | AF26: 74100 | AG26: 45355 | AH26: 2849.02 | AI26: 45338 | AJ26: 2004 | AK26: 45303 | AP26: Endy Carvalho Consultoria imobiliária | AT26: 45503 | AU26: 45503 | AV26: VENDA FINALIZADA | AW26: 45307 | AX26: 19929 | AY26: 205767.22 | BA26: FSA09 | BB26: 19929 | BD26: Formosa | BE26: Goiás | BF26: 5561996646328 | BG26: RUA 07 QUADRA 18 | BH26: 73805280 | BI26: JARDIM OLIVEIRA | BJ26: biancaalves2001fsa@gmail.com | BL26: 2200 | BM26: 45479 | BQ26: 3166 | BR26: 5398 | BS26: Professor | BT26: 45300 | BW26: sim | BY26: MP134442 | BZ26: 45300 | CA26: 45330 | CC26: 45303 | CD26: Sim | CF26: 45300 | CG26: 45308 | CI26: 45317 | CL26: 45307 | CM26: 45336 | CN26: 45306 | CO26: 45337 | CP26: 45341 | CR26: 45306 | CS26: 45323 | CT26: 45479 | CV26: 45338 | CW26: 45323 | CY26: Sim | DD26: 45336 | DF26: 45355 | DI26: 45357 | DJ26: 45302 | DK26: 45338 | DL26: 45341 | DM26: 45358 | DN26: 45383 | DO26: 45323 | DP26: OK
A27: 3206 | B27: PROCESSO FINALIZADO | C27: 3739 | D27: FSA009 - VILA DOS IPÊS | E27: Única | F27: BLOCO G | G27: 201 | H27: FORMOSA | I27: LORRANE STEFANY DE ARAUJO | J27: "05791544162" | K27: EQUIPE PRÓPRIA |FSA | L27: KÁLITA CRISTINE MARTINS FRADE - CLT | M27: Não | N27: Não | O27: Não | P27: Não | Q27: Não | R27: Não | S27: Não | T27: 161523.69 | U27: 775.27 | V27: 0 | W27: 157026.69 | X27: 48475.31 | Y27: 0 | Z27: 205502 | AA27: 0 | AB27: 0 | AD27: 8787718954967 | AE27: Contrato Adimplente | AF27: 74066 | AG27: 45356 | AH27: 3171.52 | AI27: 45315 | AJ27: 2004 | AK27: 45306 | AP27: Endy Carvalho Consultoria imobiliária | AT27: 45484 | AU27: 45484 | AV27: VENDA FINALIZADA | AW27: 45307 | AX27: 19930 | AY27: 215323.69 | BA27: FSA09 | BB27: 19930 | BD27: Formosa | BE27: Goiás | BF27: 5561998236829 | BG27: AVENIDA FORMOSA QUADRA 46 | BH27: 73813250 | BI27: FORMOSINHA | BJ27: lorranearauj488@gmail.com | BL27: 2584.25 | BM27: 45382 | BQ27: 3124 | BR27: 5399 | BS27: Assistente | BT27: 45302 | BW27: sim | BY27: MP134444 | BZ27: 45302 | CA27: 45320 | CC27: 45307 | CD27: Sim | CF27: 45302 | CL27: 45307 | CM27: 45345 | CN27: 45307 | CO27: 45323 | CP27: 45336 | CR27: 45308 | CS27: 45309 | CT27: 45382 | CV27: 45338 | CW27: 45308 | CY27: Sim | DB27: 45309 | DD27: 45337 | DE27: 45314 | DF27: 45356 | DI27: 45357 | DJ27: 45302 | DK27: 45338 | DL27: 45379 | DM27: 45358 | DN27: 45383 | DO27: 45308 | DP27: OK
